{
  "cycle_completed_at": "2025-08-01T16:18:38.027207",
  "errors_detected": 0,
  "fixes_attempted": 0,
  "fixes_successful": 0,
  "test_results": {
    "success": false,
    "output": "============================= test session starts ==============================\nplatform linux -- Python 3.12.3, pytest-7.4.3, pluggy-1.6.0 -- /media/kensan/LinuxHDD/ITSM-ITmanagementSystem/backend/venv/bin/python\ncachedir: .pytest_cache\nrootdir: /media/kensan/LinuxHDD/ITSM-ITmanagementSystem\nconfigfile: pytest.ini\nplugins: Faker-37.5.3, cov-4.1.0, asyncio-0.21.1, anyio-3.7.1, xdist-3.4.0, mock-3.12.0\nasyncio: mode=Mode.STRICT\ncollecting ... collected 30 items\n\ntests/api/test_auth.py::TestAuthAPI::test_login_success ERROR            [  3%]\ntests/api/test_auth.py::TestAuthAPI::test_login_invalid_credentials ERROR [  6%]\ntests/api/test_auth.py::TestAuthAPI::test_login_missing_credentials ERROR [ 10%]\ntests/api/test_auth.py::TestAuthAPI::test_register_success ERROR         [ 13%]\ntests/api/test_auth.py::TestAuthAPI::test_register_duplicate_email ERROR [ 16%]\ntests/api/test_auth.py::TestAuthAPI::test_register_invalid_email ERROR   [ 20%]\ntests/api/test_auth.py::TestAuthAPI::test_get_current_user ERROR         [ 23%]\ntests/api/test_auth.py::TestAuthAPI::test_get_current_user_unauthorized ERROR [ 26%]\ntests/api/test_auth.py::TestAuthAPI::test_token_refresh ERROR            [ 30%]\ntests/api/test_auth.py::TestAuthAPI::test_logout ERROR                   [ 33%]\ntests/api/test_auth.py::TestAuthAPI::test_change_password ERROR          [ 36%]\ntests/api/test_auth.py::TestAuthAPI::test_change_password_invalid_current ERROR [ 40%]\ntests/api/test_auth.py::TestAuthAPI::test_forgot_password ERROR          [ 43%]\ntests/api/test_auth.py::TestAuthAPI::test_reset_password ERROR           [ 46%]\ntests/api/test_auth.py::TestAuthAPI::test_verify_token ERROR             [ 50%]\ntests/api/test_auth.py::TestAuthAPI::test_verify_invalid_token ERROR     [ 53%]\ntests/api/test_incidents.py::TestIncidentAPI::test_get_incidents_list ERROR [ 56%]\ntests/api/test_incidents.py::TestIncidentAPI::test_create_incident ERROR [ 60%]\ntests/api/test_incidents.py::TestIncidentAPI::test_get_incident_by_id ERROR [ 63%]\ntests/api/test_incidents.py::TestIncidentAPI::test_update_incident ERROR [ 66%]\ntests/api/test_incidents.py::TestIncidentAPI::test_delete_incident ERROR [ 70%]\ntests/api/test_incidents.py::TestIncidentAPI::test_filter_incidents_by_status ERROR [ 73%]\ntests/api/test_incidents.py::TestIncidentAPI::test_filter_incidents_by_priority ERROR [ 76%]\ntests/api/test_incidents.py::TestIncidentAPI::test_search_incidents ERROR [ 80%]\ntests/api/test_incidents.py::TestIncidentAPI::test_assign_incident ERROR [ 83%]\ntests/api/test_incidents.py::TestIncidentAPI::test_incident_validation_errors ERROR [ 86%]\ntests/api/test_incidents.py::TestIncidentAPI::test_incident_access_requires_auth ERROR [ 90%]\ntests/api/test_incidents.py::TestIncidentAPI::test_incident_crud_with_auth ERROR [ 93%]\ntests/api/test_incidents.py::TestIncidentAPIAsync::test_async_get_incidents FAILED [ 96%]\ntests/api/test_incidents.py::TestIncidentAPIAsync::test_async_create_incident FAILED [100%]\n\n==================================== ERRORS ====================================\n_______________ ERROR at setup of TestAuthAPI.test_login_success _______________\ntests/conftest.py:91: in client\n    with TestClient(app) as test_client:\nvenv/lib/python3.12/site-packages/starlette/testclient.py:745: in __enter__\n    portal.call(self.wait_startup)\nvenv/lib/python3.12/site-packages/anyio/from_thread.py:277: in call\n    return cast(T_Retval, self.start_task_soon(func, *args).result())\n/usr/lib/python3.12/concurrent/futures/_base.py:449: in result\n    return self.__get_result()\n/usr/lib/python3.12/concurrent/futures/_base.py:401: in __get_result\n    raise self._exception\nvenv/lib/python3.12/site-packages/anyio/from_thread.py:217: in _call_func\n    retval = await retval\nvenv/lib/python3.12/site-packages/starlette/testclient.py:774: in wait_startup\n    message = await receive()\nvenv/lib/python3.12/site-packages/starlette/testclient.py:771: in receive\n    self.task.result()\n/usr/lib/python3.12/concurrent/futures/_base.py:449: in result\n    return self.__get_result()\n/usr/lib/python3.12/concurrent/futures/_base.py:401: in __get_result\n    raise self._exception\nvenv/lib/python3.12/site-packages/anyio/from_thread.py:217: in _call_func\n    retval = await retval\nvenv/lib/python3.12/site-packages/starlette/testclient.py:761: in lifespan\n    await self.app(scope, self.stream_receive.receive, self.stream_send.send)\nvenv/lib/python3.12/site-packages/starlette/testclient.py:56: in __call__\n    await instance(receive, send)\nE   TypeError: object Mock can't be used in 'await' expression\n_________ ERROR at setup of TestAuthAPI.test_login_invalid_credentials _________\ntests/conftest.py:91: in client\n    with TestClient(app) as test_client:\nvenv/lib/python3.12/site-packages/starlette/testclient.py:745: in __enter__\n    portal.call(self.wait_startup)\nvenv/lib/python3.12/site-packages/anyio/from_thread.py:277: in call\n    return cast(T_Retval, self.start_task_soon(func, *args).result())\n/usr/lib/python3.12/concurrent/futures/_base.py:456: in result\n    return self.__get_result()\n/usr/lib/python3.12/concurrent/futures/_base.py:401: in __get_result\n    raise self._exception\nvenv/lib/python3.12/site-packages/anyio/from_thread.py:217: in _call_func\n    retval = await retval\nvenv/lib/python3.12/site-packages/starlette/testclient.py:774: in wait_startup\n    message = await receive()\nvenv/lib/python3.12/site-packages/starlette/testclient.py:771: in receive\n    self.task.result()\n/usr/lib/python3.12/concurrent/futures/_base.py:449: in result\n    return self.__get_result()\n/usr/lib/python3.12/concurrent/futures/_base.py:401: in __get_result\n    raise self._exception\nvenv/lib/python3.12/site-packages/anyio/from_thread.py:217: in _call_func\n    retval = await retval\nvenv/lib/python3.12/site-packages/starlette/testclient.py:761: in lifespan\n    await self.app(scope, self.stream_receive.receive, self.stream_send.send)\nvenv/lib/python3.12/site-packages/starlette/testclient.py:56: in __call__\n    await instance(receive, send)\nE   TypeError: object Mock can't be used in 'await' expression\n_________ ERROR at setup of TestAuthAPI.test_login_missing_credentials _________\ntests/conftest.py:91: in client\n    with TestClient(app) as test_client:\nvenv/lib/python3.12/site-packages/starlette/testclient.py:745: in __enter__\n    portal.call(self.wait_startup)\nvenv/lib/python3.12/site-packages/anyio/from_thread.py:277: in call\n    return cast(T_Retval, self.start_task_soon(func, *args).result())\n/usr/lib/python3.12/concurrent/futures/_base.py:449: in result\n    return self.__get_result()\n/usr/lib/python3.12/concurrent/futures/_base.py:401: in __get_result\n    raise self._exception\nvenv/lib/python3.12/site-packages/anyio/from_thread.py:217: in _call_func\n    retval = await retval\nvenv/lib/python3.12/site-packages/starlette/testclient.py:774: in wait_startup\n    message = await receive()\nvenv/lib/python3.12/site-packages/starlette/testclient.py:771: in receive\n    self.task.result()\n/usr/lib/python3.12/concurrent/futures/_base.py:449: in result\n    return self.__get_result()\n/usr/lib/python3.12/concurrent/futures/_base.py:401: in __get_result\n    raise self._exception\nvenv/lib/python3.12/site-packages/anyio/from_thread.py:217: in _call_func\n    retval = await retval\nvenv/lib/python3.12/site-packages/starlette/testclient.py:761: in lifespan\n    await self.app(scope, self.stream_receive.receive, self.stream_send.send)\nvenv/lib/python3.12/site-packages/starlette/testclient.py:56: in __call__\n    await instance(receive, send)\nE   TypeError: object Mock can't be used in 'await' expression\n_____________ ERROR at setup of TestAuthAPI.test_register_success ______________\ntests/conftest.py:91: in client\n    with TestClient(app) as test_client:\nvenv/lib/python3.12/site-packages/starlette/testclient.py:745: in __enter__\n    portal.call(self.wait_startup)\nvenv/lib/python3.12/site-packages/anyio/from_thread.py:277: in call\n    return cast(T_Retval, self.start_task_soon(func, *args).result())\n/usr/lib/python3.12/concurrent/futures/_base.py:456: in result\n    return self.__get_result()\n/usr/lib/python3.12/concurrent/futures/_base.py:401: in __get_result\n    raise self._exception\nvenv/lib/python3.12/site-packages/anyio/from_thread.py:217: in _call_func\n    retval = await retval\nvenv/lib/python3.12/site-packages/starlette/testclient.py:774: in wait_startup\n    message = await receive()\nvenv/lib/python3.12/site-packages/starlette/testclient.py:771: in receive\n    self.task.result()\n/usr/lib/python3.12/concurrent/futures/_base.py:449: in result\n    return self.__get_result()\n/usr/lib/python3.12/concurrent/futures/_base.py:401: in __get_result\n    raise self._exception\nvenv/lib/python3.12/site-packages/anyio/from_thread.py:217: in _call_func\n    retval = await retval\nvenv/lib/python3.12/site-packages/starlette/testclient.py:761: in lifespan\n    await self.app(scope, self.stream_receive.receive, self.stream_send.send)\nvenv/lib/python3.12/site-packages/starlette/testclient.py:56: in __call__\n    await instance(receive, send)\nE   TypeError: object Mock can't be used in 'await' expression\n_________ ERROR at setup of TestAuthAPI.test_register_duplicate_email __________\ntests/conftest.py:91: in client\n    with TestClient(app) as test_client:\nvenv/lib/python3.12/site-packages/starlette/testclient.py:745: in __enter__\n    portal.call(self.wait_startup)\nvenv/lib/python3.12/site-packages/anyio/from_thread.py:277: in call\n    return cast(T_Retval, self.start_task_soon(func, *args).result())\n/usr/lib/python3.12/concurrent/futures/_base.py:449: in result\n    return self.__get_result()\n/usr/lib/python3.12/concurrent/futures/_base.py:401: in __get_result\n    raise self._exception\nvenv/lib/python3.12/site-packages/anyio/from_thread.py:217: in _call_func\n    retval = await retval\nvenv/lib/python3.12/site-packages/starlette/testclient.py:774: in wait_startup\n    message = await receive()\nvenv/lib/python3.12/site-packages/starlette/testclient.py:771: in receive\n    self.task.result()\n/usr/lib/python3.12/concurrent/futures/_base.py:449: in result\n    return self.__get_result()\n/usr/lib/python3.12/concurrent/futures/_base.py:401: in __get_result\n    raise self._exception\nvenv/lib/python3.12/site-packages/anyio/from_thread.py:217: in _call_func\n    retval = await retval\nvenv/lib/python3.12/site-packages/starlette/testclient.py:761: in lifespan\n    await self.app(scope, self.stream_receive.receive, self.stream_send.send)\nvenv/lib/python3.12/site-packages/starlette/testclient.py:56: in __call__\n    await instance(receive, send)\nE   TypeError: object Mock can't be used in 'await' expression\n__________ ERROR at setup of TestAuthAPI.test_register_invalid_email ___________\ntests/conftest.py:91: in client\n    with TestClient(app) as test_client:\nvenv/lib/python3.12/site-packages/starlette/testclient.py:745: in __enter__\n    portal.call(self.wait_startup)\nvenv/lib/python3.12/site-packages/anyio/from_thread.py:277: in call\n    return cast(T_Retval, self.start_task_soon(func, *args).result())\n/usr/lib/python3.12/concurrent/futures/_base.py:456: in result\n    return self.__get_result()\n/usr/lib/python3.12/concurrent/futures/_base.py:401: in __get_result\n    raise self._exception\nvenv/lib/python3.12/site-packages/anyio/from_thread.py:217: in _call_func\n    retval = await retval\nvenv/lib/python3.12/site-packages/starlette/testclient.py:774: in wait_startup\n    message = await receive()\nvenv/lib/python3.12/site-packages/starlette/testclient.py:771: in receive\n    self.task.result()\n/usr/lib/python3.12/concurrent/futures/_base.py:449: in result\n    return self.__get_result()\n/usr/lib/python3.12/concurrent/futures/_base.py:401: in __get_result\n    raise self._exception\nvenv/lib/python3.12/site-packages/anyio/from_thread.py:217: in _call_func\n    retval = await retval\nvenv/lib/python3.12/site-packages/starlette/testclient.py:761: in lifespan\n    await self.app(scope, self.stream_receive.receive, self.stream_send.send)\nvenv/lib/python3.12/site-packages/starlette/testclient.py:56: in __call__\n    await instance(receive, send)\nE   TypeError: object Mock can't be used in 'await' expression\n_____________ ERROR at setup of TestAuthAPI.test_get_current_user ______________\ntests/conftest.py:91: in client\n    with TestClient(app) as test_client:\nvenv/lib/python3.12/site-packages/starlette/testclient.py:745: in __enter__\n    portal.call(self.wait_startup)\nvenv/lib/python3.12/site-packages/anyio/from_thread.py:277: in call\n    return cast(T_Retval, self.start_task_soon(func, *args).result())\n/usr/lib/python3.12/concurrent/futures/_base.py:449: in result\n    return self.__get_result()\n/usr/lib/python3.12/concurrent/futures/_base.py:401: in __get_result\n    raise self._exception\nvenv/lib/python3.12/site-packages/anyio/from_thread.py:217: in _call_func\n    retval = await retval\nvenv/lib/python3.12/site-packages/starlette/testclient.py:774: in wait_startup\n    message = await receive()\nvenv/lib/python3.12/site-packages/starlette/testclient.py:771: in receive\n    self.task.result()\n/usr/lib/python3.12/concurrent/futures/_base.py:449: in result\n    return self.__get_result()\n/usr/lib/python3.12/concurrent/futures/_base.py:401: in __get_result\n    raise self._exception\nvenv/lib/python3.12/site-packages/anyio/from_thread.py:217: in _call_func\n    retval = await retval\nvenv/lib/python3.12/site-packages/starlette/testclient.py:761: in lifespan\n    await self.app(scope, self.stream_receive.receive, self.stream_send.send)\nvenv/lib/python3.12/site-packages/starlette/testclient.py:56: in __call__\n    await instance(receive, send)\nE   TypeError: object Mock can't be used in 'await' expression\n_______ ERROR at setup of TestAuthAPI.test_get_current_user_unauthorized _______\ntests/conftest.py:91: in client\n    with TestClient(app) as test_client:\nvenv/lib/python3.12/site-packages/starlette/testclient.py:745: in __enter__\n    portal.call(self.wait_startup)\nvenv/lib/python3.12/site-packages/anyio/from_thread.py:277: in call\n    return cast(T_Retval, self.start_task_soon(func, *args).result())\n/usr/lib/python3.12/concurrent/futures/_base.py:456: in result\n    return self.__get_result()\n/usr/lib/python3.12/concurrent/futures/_base.py:401: in __get_result\n    raise self._exception\nvenv/lib/python3.12/site-packages/anyio/from_thread.py:217: in _call_func\n    retval = await retval\nvenv/lib/python3.12/site-packages/starlette/testclient.py:774: in wait_startup\n    message = await receive()\nvenv/lib/python3.12/site-packages/starlette/testclient.py:771: in receive\n    self.task.result()\n/usr/lib/python3.12/concurrent/futures/_base.py:449: in result\n    return self.__get_result()\n/usr/lib/python3.12/concurrent/futures/_base.py:401: in __get_result\n    raise self._exception\nvenv/lib/python3.12/site-packages/anyio/from_thread.py:217: in _call_func\n    retval = await retval\nvenv/lib/python3.12/site-packages/starlette/testclient.py:761: in lifespan\n    await self.app(scope, self.stream_receive.receive, self.stream_send.send)\nvenv/lib/python3.12/site-packages/starlette/testclient.py:56: in __call__\n    await instance(receive, send)\nE   TypeError: object Mock can't be used in 'await' expression\n_______________ ERROR at setup of TestAuthAPI.test_token_refresh _______________\ntests/conftest.py:91: in client\n    with TestClient(app) as test_client:\nvenv/lib/python3.12/site-packages/starlette/testclient.py:745: in __enter__\n    portal.call(self.wait_startup)\nvenv/lib/python3.12/site-packages/anyio/from_thread.py:277: in call\n    return cast(T_Retval, self.start_task_soon(func, *args).result())\n/usr/lib/python3.12/concurrent/futures/_base.py:449: in result\n    return self.__get_result()\n/usr/lib/python3.12/concurrent/futures/_base.py:401: in __get_result\n    raise self._exception\nvenv/lib/python3.12/site-packages/anyio/from_thread.py:217: in _call_func\n    retval = await retval\nvenv/lib/python3.12/site-packages/starlette/testclient.py:774: in wait_startup\n    message = await receive()\nvenv/lib/python3.12/site-packages/starlette/testclient.py:771: in receive\n    self.task.result()\n/usr/lib/python3.12/concurrent/futures/_base.py:449: in result\n    return self.__get_result()\n/usr/lib/python3.12/concurrent/futures/_base.py:401: in __get_result\n    raise self._exception\nvenv/lib/python3.12/site-packages/anyio/from_thread.py:217: in _call_func\n    retval = await retval\nvenv/lib/python3.12/site-packages/starlette/testclient.py:761: in lifespan\n    await self.app(scope, self.stream_receive.receive, self.stream_send.send)\nvenv/lib/python3.12/site-packages/starlette/testclient.py:56: in __call__\n    await instance(receive, send)\nE   TypeError: object Mock can't be used in 'await' expression\n__________________ ERROR at setup of TestAuthAPI.test_logout ___________________\ntests/conftest.py:91: in client\n    with TestClient(app) as test_client:\nvenv/lib/python3.12/site-packages/starlette/testclient.py:745: in __enter__\n    portal.call(self.wait_startup)\nvenv/lib/python3.12/site-packages/anyio/from_thread.py:277: in call\n    return cast(T_Retval, self.start_task_soon(func, *args).result())\n/usr/lib/python3.12/concurrent/futures/_base.py:456: in result\n    return self.__get_result()\n/usr/lib/python3.12/concurrent/futures/_base.py:401: in __get_result\n    raise self._exception\nvenv/lib/python3.12/site-packages/anyio/from_thread.py:217: in _call_func\n    retval = await retval\nvenv/lib/python3.12/site-packages/starlette/testclient.py:774: in wait_startup\n    message = await receive()\nvenv/lib/python3.12/site-packages/starlette/testclient.py:771: in receive\n    self.task.result()\n/usr/lib/python3.12/concurrent/futures/_base.py:449: in result\n    return self.__get_result()\n/usr/lib/python3.12/concurrent/futures/_base.py:401: in __get_result\n    raise self._exception\nvenv/lib/python3.12/site-packages/anyio/from_thread.py:217: in _call_func\n    retval = await retval\nvenv/lib/python3.12/site-packages/starlette/testclient.py:761: in lifespan\n    await self.app(scope, self.stream_receive.receive, self.stream_send.send)\nvenv/lib/python3.12/site-packages/starlette/testclient.py:56: in __call__\n    await instance(receive, send)\nE   TypeError: object Mock can't be used in 'await' expression\n______________ ERROR at setup of TestAuthAPI.test_change_password ______________\ntests/conftest.py:91: in client\n    with TestClient(app) as test_client:\nvenv/lib/python3.12/site-packages/starlette/testclient.py:745: in __enter__\n    portal.call(self.wait_startup)\nvenv/lib/python3.12/site-packages/anyio/from_thread.py:277: in call\n    return cast(T_Retval, self.start_task_soon(func, *args).result())\n/usr/lib/python3.12/concurrent/futures/_base.py:449: in result\n    return self.__get_result()\n/usr/lib/python3.12/concurrent/futures/_base.py:401: in __get_result\n    raise self._exception\nvenv/lib/python3.12/site-packages/anyio/from_thread.py:217: in _call_func\n    retval = await retval\nvenv/lib/python3.12/site-packages/starlette/testclient.py:774: in wait_startup\n    message = await receive()\nvenv/lib/python3.12/site-packages/starlette/testclient.py:771: in receive\n    self.task.result()\n/usr/lib/python3.12/concurrent/futures/_base.py:449: in result\n    return self.__get_result()\n/usr/lib/python3.12/concurrent/futures/_base.py:401: in __get_result\n    raise self._exception\nvenv/lib/python3.12/site-packages/anyio/from_thread.py:217: in _call_func\n    retval = await retval\nvenv/lib/python3.12/site-packages/starlette/testclient.py:761: in lifespan\n    await self.app(scope, self.stream_receive.receive, self.stream_send.send)\nvenv/lib/python3.12/site-packages/starlette/testclient.py:56: in __call__\n    await instance(receive, send)\nE   TypeError: object Mock can't be used in 'await' expression\n______ ERROR at setup of TestAuthAPI.test_change_password_invalid_current ______\ntests/conftest.py:91: in client\n    with TestClient(app) as test_client:\nvenv/lib/python3.12/site-packages/starlette/testclient.py:745: in __enter__\n    portal.call(self.wait_startup)\nvenv/lib/python3.12/site-packages/anyio/from_thread.py:277: in call\n    return cast(T_Retval, self.start_task_soon(func, *args).result())\n/usr/lib/python3.12/concurrent/futures/_base.py:456: in result\n    return self.__get_result()\n/usr/lib/python3.12/concurrent/futures/_base.py:401: in __get_result\n    raise self._exception\nvenv/lib/python3.12/site-packages/anyio/from_thread.py:217: in _call_func\n    retval = await retval\nvenv/lib/python3.12/site-packages/starlette/testclient.py:774: in wait_startup\n    message = await receive()\nvenv/lib/python3.12/site-packages/starlette/testclient.py:771: in receive\n    self.task.result()\n/usr/lib/python3.12/concurrent/futures/_base.py:449: in result\n    return self.__get_result()\n/usr/lib/python3.12/concurrent/futures/_base.py:401: in __get_result\n    raise self._exception\nvenv/lib/python3.12/site-packages/anyio/from_thread.py:217: in _call_func\n    retval = await retval\nvenv/lib/python3.12/site-packages/starlette/testclient.py:761: in lifespan\n    await self.app(scope, self.stream_receive.receive, self.stream_send.send)\nvenv/lib/python3.12/site-packages/starlette/testclient.py:56: in __call__\n    await instance(receive, send)\nE   TypeError: object Mock can't be used in 'await' expression\n______________ ERROR at setup of TestAuthAPI.test_forgot_password ______________\ntests/conftest.py:91: in client\n    with TestClient(app) as test_client:\nvenv/lib/python3.12/site-packages/starlette/testclient.py:745: in __enter__\n    portal.call(self.wait_startup)\nvenv/lib/python3.12/site-packages/anyio/from_thread.py:277: in call\n    return cast(T_Retval, self.start_task_soon(func, *args).result())\n/usr/lib/python3.12/concurrent/futures/_base.py:449: in result\n    return self.__get_result()\n/usr/lib/python3.12/concurrent/futures/_base.py:401: in __get_result\n    raise self._exception\nvenv/lib/python3.12/site-packages/anyio/from_thread.py:217: in _call_func\n    retval = await retval\nvenv/lib/python3.12/site-packages/starlette/testclient.py:774: in wait_startup\n    message = await receive()\nvenv/lib/python3.12/site-packages/starlette/testclient.py:771: in receive\n    self.task.result()\n/usr/lib/python3.12/concurrent/futures/_base.py:449: in result\n    return self.__get_result()\n/usr/lib/python3.12/concurrent/futures/_base.py:401: in __get_result\n    raise self._exception\nvenv/lib/python3.12/site-packages/anyio/from_thread.py:217: in _call_func\n    retval = await retval\nvenv/lib/python3.12/site-packages/starlette/testclient.py:761: in lifespan\n    await self.app(scope, self.stream_receive.receive, self.stream_send.send)\nvenv/lib/python3.12/site-packages/starlette/testclient.py:56: in __call__\n    await instance(receive, send)\nE   TypeError: object Mock can't be used in 'await' expression\n______________ ERROR at setup of TestAuthAPI.test_reset_password _______________\ntests/conftest.py:91: in client\n    with TestClient(app) as test_client:\nvenv/lib/python3.12/site-packages/starlette/testclient.py:745: in __enter__\n    portal.call(self.wait_startup)\nvenv/lib/python3.12/site-packages/anyio/from_thread.py:277: in call\n    return cast(T_Retval, self.start_task_soon(func, *args).result())\n/usr/lib/python3.12/concurrent/futures/_base.py:449: in result\n    return self.__get_result()\n/usr/lib/python3.12/concurrent/futures/_base.py:401: in __get_result\n    raise self._exception\nvenv/lib/python3.12/site-packages/anyio/from_thread.py:217: in _call_func\n    retval = await retval\nvenv/lib/python3.12/site-packages/starlette/testclient.py:774: in wait_startup\n    message = await receive()\nvenv/lib/python3.12/site-packages/starlette/testclient.py:771: in receive\n    self.task.result()\n/usr/lib/python3.12/concurrent/futures/_base.py:449: in result\n    return self.__get_result()\n/usr/lib/python3.12/concurrent/futures/_base.py:401: in __get_result\n    raise self._exception\nvenv/lib/python3.12/site-packages/anyio/from_thread.py:217: in _call_func\n    retval = await retval\nvenv/lib/python3.12/site-packages/starlette/testclient.py:761: in lifespan\n    await self.app(scope, self.stream_receive.receive, self.stream_send.send)\nvenv/lib/python3.12/site-packages/starlette/testclient.py:56: in __call__\n    await instance(receive, send)\nE   TypeError: object Mock can't be used in 'await' expression\n_______________ ERROR at setup of TestAuthAPI.test_verify_token ________________\ntests/conftest.py:91: in client\n    with TestClient(app) as test_client:\nvenv/lib/python3.12/site-packages/starlette/testclient.py:745: in __enter__\n    portal.call(self.wait_startup)\nvenv/lib/python3.12/site-packages/anyio/from_thread.py:277: in call\n    return cast(T_Retval, self.start_task_soon(func, *args).result())\n/usr/lib/python3.12/concurrent/futures/_base.py:456: in result\n    return self.__get_result()\n/usr/lib/python3.12/concurrent/futures/_base.py:401: in __get_result\n    raise self._exception\nvenv/lib/python3.12/site-packages/anyio/from_thread.py:217: in _call_func\n    retval = await retval\nvenv/lib/python3.12/site-packages/starlette/testclient.py:774: in wait_startup\n    message = await receive()\nvenv/lib/python3.12/site-packages/starlette/testclient.py:771: in receive\n    self.task.result()\n/usr/lib/python3.12/concurrent/futures/_base.py:449: in result\n    return self.__get_result()\n/usr/lib/python3.12/concurrent/futures/_base.py:401: in __get_result\n    raise self._exception\nvenv/lib/python3.12/site-packages/anyio/from_thread.py:217: in _call_func\n    retval = await retval\nvenv/lib/python3.12/site-packages/starlette/testclient.py:761: in lifespan\n    await self.app(scope, self.stream_receive.receive, self.stream_send.send)\nvenv/lib/python3.12/site-packages/starlette/testclient.py:56: in __call__\n    await instance(receive, send)\nE   TypeError: object Mock can't be used in 'await' expression\n___________ ERROR at setup of TestAuthAPI.test_verify_invalid_token ____________\ntests/conftest.py:91: in client\n    with TestClient(app) as test_client:\nvenv/lib/python3.12/site-packages/starlette/testclient.py:745: in __enter__\n    portal.call(self.wait_startup)\nvenv/lib/python3.12/site-packages/anyio/from_thread.py:277: in call\n    return cast(T_Retval, self.start_task_soon(func, *args).result())\n/usr/lib/python3.12/concurrent/futures/_base.py:449: in result\n    return self.__get_result()\n/usr/lib/python3.12/concurrent/futures/_base.py:401: in __get_result\n    raise self._exception\nvenv/lib/python3.12/site-packages/anyio/from_thread.py:217: in _call_func\n    retval = await retval\nvenv/lib/python3.12/site-packages/starlette/testclient.py:774: in wait_startup\n    message = await receive()\nvenv/lib/python3.12/site-packages/starlette/testclient.py:771: in receive\n    self.task.result()\n/usr/lib/python3.12/concurrent/futures/_base.py:449: in result\n    return self.__get_result()\n/usr/lib/python3.12/concurrent/futures/_base.py:401: in __get_result\n    raise self._exception\nvenv/lib/python3.12/site-packages/anyio/from_thread.py:217: in _call_func\n    retval = await retval\nvenv/lib/python3.12/site-packages/starlette/testclient.py:761: in lifespan\n    await self.app(scope, self.stream_receive.receive, self.stream_send.send)\nvenv/lib/python3.12/site-packages/starlette/testclient.py:56: in __call__\n    await instance(receive, send)\nE   TypeError: object Mock can't be used in 'await' expression\n__________ ERROR at setup of TestIncidentAPI.test_get_incidents_list ___________\ntests/conftest.py:91: in client\n    with TestClient(app) as test_client:\nvenv/lib/python3.12/site-packages/starlette/testclient.py:745: in __enter__\n    portal.call(self.wait_startup)\nvenv/lib/python3.12/site-packages/anyio/from_thread.py:277: in call\n    return cast(T_Retval, self.start_task_soon(func, *args).result())\n/usr/lib/python3.12/concurrent/futures/_base.py:449: in result\n    return self.__get_result()\n/usr/lib/python3.12/concurrent/futures/_base.py:401: in __get_result\n    raise self._exception\nvenv/lib/python3.12/site-packages/anyio/from_thread.py:217: in _call_func\n    retval = await retval\nvenv/lib/python3.12/site-packages/starlette/testclient.py:774: in wait_startup\n    message = await receive()\nvenv/lib/python3.12/site-packages/starlette/testclient.py:771: in receive\n    self.task.result()\n/usr/lib/python3.12/concurrent/futures/_base.py:449: in result\n    return self.__get_result()\n/usr/lib/python3.12/concurrent/futures/_base.py:401: in __get_result\n    raise self._exception\nvenv/lib/python3.12/site-packages/anyio/from_thread.py:217: in _call_func\n    retval = await retval\nvenv/lib/python3.12/site-packages/starlette/testclient.py:761: in lifespan\n    await self.app(scope, self.stream_receive.receive, self.stream_send.send)\nvenv/lib/python3.12/site-packages/starlette/testclient.py:56: in __call__\n    await instance(receive, send)\nE   TypeError: object Mock can't be used in 'await' expression\n____________ ERROR at setup of TestIncidentAPI.test_create_incident ____________\ntests/conftest.py:91: in client\n    with TestClient(app) as test_client:\nvenv/lib/python3.12/site-packages/starlette/testclient.py:745: in __enter__\n    portal.call(self.wait_startup)\nvenv/lib/python3.12/site-packages/anyio/from_thread.py:277: in call\n    return cast(T_Retval, self.start_task_soon(func, *args).result())\n/usr/lib/python3.12/concurrent/futures/_base.py:449: in result\n    return self.__get_result()\n/usr/lib/python3.12/concurrent/futures/_base.py:401: in __get_result\n    raise self._exception\nvenv/lib/python3.12/site-packages/anyio/from_thread.py:217: in _call_func\n    retval = await retval\nvenv/lib/python3.12/site-packages/starlette/testclient.py:774: in wait_startup\n    message = await receive()\nvenv/lib/python3.12/site-packages/starlette/testclient.py:771: in receive\n    self.task.result()\n/usr/lib/python3.12/concurrent/futures/_base.py:449: in result\n    return self.__get_result()\n/usr/lib/python3.12/concurrent/futures/_base.py:401: in __get_result\n    raise self._exception\nvenv/lib/python3.12/site-packages/anyio/from_thread.py:217: in _call_func\n    retval = await retval\nvenv/lib/python3.12/site-packages/starlette/testclient.py:761: in lifespan\n    await self.app(scope, self.stream_receive.receive, self.stream_send.send)\nvenv/lib/python3.12/site-packages/starlette/testclient.py:56: in __call__\n    await instance(receive, send)\nE   TypeError: object Mock can't be used in 'await' expression\n__________ ERROR at setup of TestIncidentAPI.test_get_incident_by_id ___________\ntests/conftest.py:91: in client\n    with TestClient(app) as test_client:\nvenv/lib/python3.12/site-packages/starlette/testclient.py:745: in __enter__\n    portal.call(self.wait_startup)\nvenv/lib/python3.12/site-packages/anyio/from_thread.py:277: in call\n    return cast(T_Retval, self.start_task_soon(func, *args).result())\n/usr/lib/python3.12/concurrent/futures/_base.py:456: in result\n    return self.__get_result()\n/usr/lib/python3.12/concurrent/futures/_base.py:401: in __get_result\n    raise self._exception\nvenv/lib/python3.12/site-packages/anyio/from_thread.py:217: in _call_func\n    retval = await retval\nvenv/lib/python3.12/site-packages/starlette/testclient.py:774: in wait_startup\n    message = await receive()\nvenv/lib/python3.12/site-packages/starlette/testclient.py:771: in receive\n    self.task.result()\n/usr/lib/python3.12/concurrent/futures/_base.py:449: in result\n    return self.__get_result()\n/usr/lib/python3.12/concurrent/futures/_base.py:401: in __get_result\n    raise self._exception\nvenv/lib/python3.12/site-packages/anyio/from_thread.py:217: in _call_func\n    retval = await retval\nvenv/lib/python3.12/site-packages/starlette/testclient.py:761: in lifespan\n    await self.app(scope, self.stream_receive.receive, self.stream_send.send)\nvenv/lib/python3.12/site-packages/starlette/testclient.py:56: in __call__\n    await instance(receive, send)\nE   TypeError: object Mock can't be used in 'await' expression\n____________ ERROR at setup of TestIncidentAPI.test_update_incident ____________\ntests/conftest.py:91: in client\n    with TestClient(app) as test_client:\nvenv/lib/python3.12/site-packages/starlette/testclient.py:745: in __enter__\n    portal.call(self.wait_startup)\nvenv/lib/python3.12/site-packages/anyio/from_thread.py:277: in call\n    return cast(T_Retval, self.start_task_soon(func, *args).result())\n/usr/lib/python3.12/concurrent/futures/_base.py:449: in result\n    return self.__get_result()\n/usr/lib/python3.12/concurrent/futures/_base.py:401: in __get_result\n    raise self._exception\nvenv/lib/python3.12/site-packages/anyio/from_thread.py:217: in _call_func\n    retval = await retval\nvenv/lib/python3.12/site-packages/starlette/testclient.py:774: in wait_startup\n    message = await receive()\nvenv/lib/python3.12/site-packages/starlette/testclient.py:771: in receive\n    self.task.result()\n/usr/lib/python3.12/concurrent/futures/_base.py:449: in result\n    return self.__get_result()\n/usr/lib/python3.12/concurrent/futures/_base.py:401: in __get_result\n    raise self._exception\nvenv/lib/python3.12/site-packages/anyio/from_thread.py:217: in _call_func\n    retval = await retval\nvenv/lib/python3.12/site-packages/starlette/testclient.py:761: in lifespan\n    await self.app(scope, self.stream_receive.receive, self.stream_send.send)\nvenv/lib/python3.12/site-packages/starlette/testclient.py:56: in __call__\n    await instance(receive, send)\nE   TypeError: object Mock can't be used in 'await' expression\n____________ ERROR at setup of TestIncidentAPI.test_delete_incident ____________\ntests/conftest.py:91: in client\n    with TestClient(app) as test_client:\nvenv/lib/python3.12/site-packages/starlette/testclient.py:745: in __enter__\n    portal.call(self.wait_startup)\nvenv/lib/python3.12/site-packages/anyio/from_thread.py:277: in call\n    return cast(T_Retval, self.start_task_soon(func, *args).result())\n/usr/lib/python3.12/concurrent/futures/_base.py:449: in result\n    return self.__get_result()\n/usr/lib/python3.12/concurrent/futures/_base.py:401: in __get_result\n    raise self._exception\nvenv/lib/python3.12/site-packages/anyio/from_thread.py:217: in _call_func\n    retval = await retval\nvenv/lib/python3.12/site-packages/starlette/testclient.py:774: in wait_startup\n    message = await receive()\nvenv/lib/python3.12/site-packages/starlette/testclient.py:771: in receive\n    self.task.result()\n/usr/lib/python3.12/concurrent/futures/_base.py:449: in result\n    return self.__get_result()\n/usr/lib/python3.12/concurrent/futures/_base.py:401: in __get_result\n    raise self._exception\nvenv/lib/python3.12/site-packages/anyio/from_thread.py:217: in _call_func\n    retval = await retval\nvenv/lib/python3.12/site-packages/starlette/testclient.py:761: in lifespan\n    await self.app(scope, self.stream_receive.receive, self.stream_send.send)\nvenv/lib/python3.12/site-packages/starlette/testclient.py:56: in __call__\n    await instance(receive, send)\nE   TypeError: object Mock can't be used in 'await' expression\n______ ERROR at setup of TestIncidentAPI.test_filter_incidents_by_status _______\ntests/conftest.py:91: in client\n    with TestClient(app) as test_client:\nvenv/lib/python3.12/site-packages/starlette/testclient.py:745: in __enter__\n    portal.call(self.wait_startup)\nvenv/lib/python3.12/site-packages/anyio/from_thread.py:277: in call\n    return cast(T_Retval, self.start_task_soon(func, *args).result())\n/usr/lib/python3.12/concurrent/futures/_base.py:449: in result\n    return self.__get_result()\n/usr/lib/python3.12/concurrent/futures/_base.py:401: in __get_result\n    raise self._exception\nvenv/lib/python3.12/site-packages/anyio/from_thread.py:217: in _call_func\n    retval = await retval\nvenv/lib/python3.12/site-packages/starlette/testclient.py:774: in wait_startup\n    message = await receive()\nvenv/lib/python3.12/site-packages/starlette/testclient.py:771: in receive\n    self.task.result()\n/usr/lib/python3.12/concurrent/futures/_base.py:449: in result\n    return self.__get_result()\n/usr/lib/python3.12/concurrent/futures/_base.py:401: in __get_result\n    raise self._exception\nvenv/lib/python3.12/site-packages/anyio/from_thread.py:217: in _call_func\n    retval = await retval\nvenv/lib/python3.12/site-packages/starlette/testclient.py:761: in lifespan\n    await self.app(scope, self.stream_receive.receive, self.stream_send.send)\nvenv/lib/python3.12/site-packages/starlette/testclient.py:56: in __call__\n    await instance(receive, send)\nE   TypeError: object Mock can't be used in 'await' expression\n_____ ERROR at setup of TestIncidentAPI.test_filter_incidents_by_priority ______\ntests/conftest.py:91: in client\n    with TestClient(app) as test_client:\nvenv/lib/python3.12/site-packages/starlette/testclient.py:745: in __enter__\n    portal.call(self.wait_startup)\nvenv/lib/python3.12/site-packages/anyio/from_thread.py:277: in call\n    return cast(T_Retval, self.start_task_soon(func, *args).result())\n/usr/lib/python3.12/concurrent/futures/_base.py:456: in result\n    return self.__get_result()\n/usr/lib/python3.12/concurrent/futures/_base.py:401: in __get_result\n    raise self._exception\nvenv/lib/python3.12/site-packages/anyio/from_thread.py:217: in _call_func\n    retval = await retval\nvenv/lib/python3.12/site-packages/starlette/testclient.py:774: in wait_startup\n    message = await receive()\nvenv/lib/python3.12/site-packages/starlette/testclient.py:771: in receive\n    self.task.result()\n/usr/lib/python3.12/concurrent/futures/_base.py:449: in result\n    return self.__get_result()\n/usr/lib/python3.12/concurrent/futures/_base.py:401: in __get_result\n    raise self._exception\nvenv/lib/python3.12/site-packages/anyio/from_thread.py:217: in _call_func\n    retval = await retval\nvenv/lib/python3.12/site-packages/starlette/testclient.py:761: in lifespan\n    await self.app(scope, self.stream_receive.receive, self.stream_send.send)\nvenv/lib/python3.12/site-packages/starlette/testclient.py:56: in __call__\n    await instance(receive, send)\nE   TypeError: object Mock can't be used in 'await' expression\n___________ ERROR at setup of TestIncidentAPI.test_search_incidents ____________\ntests/conftest.py:91: in client\n    with TestClient(app) as test_client:\nvenv/lib/python3.12/site-packages/starlette/testclient.py:745: in __enter__\n    portal.call(self.wait_startup)\nvenv/lib/python3.12/site-packages/anyio/from_thread.py:277: in call\n    return cast(T_Retval, self.start_task_soon(func, *args).result())\n/usr/lib/python3.12/concurrent/futures/_base.py:456: in result\n    return self.__get_result()\n/usr/lib/python3.12/concurrent/futures/_base.py:401: in __get_result\n    raise self._exception\nvenv/lib/python3.12/site-packages/anyio/from_thread.py:217: in _call_func\n    retval = await retval\nvenv/lib/python3.12/site-packages/starlette/testclient.py:774: in wait_startup\n    message = await receive()\nvenv/lib/python3.12/site-packages/starlette/testclient.py:771: in receive\n    self.task.result()\n/usr/lib/python3.12/concurrent/futures/_base.py:449: in result\n    return self.__get_result()\n/usr/lib/python3.12/concurrent/futures/_base.py:401: in __get_result\n    raise self._exception\nvenv/lib/python3.12/site-packages/anyio/from_thread.py:217: in _call_func\n    retval = await retval\nvenv/lib/python3.12/site-packages/starlette/testclient.py:761: in lifespan\n    await self.app(scope, self.stream_receive.receive, self.stream_send.send)\nvenv/lib/python3.12/site-packages/starlette/testclient.py:56: in __call__\n    await instance(receive, send)\nE   TypeError: object Mock can't be used in 'await' expression\n____________ ERROR at setup of TestIncidentAPI.test_assign_incident ____________\ntests/conftest.py:91: in client\n    with TestClient(app) as test_client:\nvenv/lib/python3.12/site-packages/starlette/testclient.py:745: in __enter__\n    portal.call(self.wait_startup)\nvenv/lib/python3.12/site-packages/anyio/from_thread.py:277: in call\n    return cast(T_Retval, self.start_task_soon(func, *args).result())\n/usr/lib/python3.12/concurrent/futures/_base.py:449: in result\n    return self.__get_result()\n/usr/lib/python3.12/concurrent/futures/_base.py:401: in __get_result\n    raise self._exception\nvenv/lib/python3.12/site-packages/anyio/from_thread.py:217: in _call_func\n    retval = await retval\nvenv/lib/python3.12/site-packages/starlette/testclient.py:774: in wait_startup\n    message = await receive()\nvenv/lib/python3.12/site-packages/starlette/testclient.py:771: in receive\n    self.task.result()\n/usr/lib/python3.12/concurrent/futures/_base.py:449: in result\n    return self.__get_result()\n/usr/lib/python3.12/concurrent/futures/_base.py:401: in __get_result\n    raise self._exception\nvenv/lib/python3.12/site-packages/anyio/from_thread.py:217: in _call_func\n    retval = await retval\nvenv/lib/python3.12/site-packages/starlette/testclient.py:761: in lifespan\n    await self.app(scope, self.stream_receive.receive, self.stream_send.send)\nvenv/lib/python3.12/site-packages/starlette/testclient.py:56: in __call__\n    await instance(receive, send)\nE   TypeError: object Mock can't be used in 'await' expression\n______ ERROR at setup of TestIncidentAPI.test_incident_validation_errors _______\ntests/conftest.py:91: in client\n    with TestClient(app) as test_client:\nvenv/lib/python3.12/site-packages/starlette/testclient.py:745: in __enter__\n    portal.call(self.wait_startup)\nvenv/lib/python3.12/site-packages/anyio/from_thread.py:277: in call\n    return cast(T_Retval, self.start_task_soon(func, *args).result())\n/usr/lib/python3.12/concurrent/futures/_base.py:449: in result\n    return self.__get_result()\n/usr/lib/python3.12/concurrent/futures/_base.py:401: in __get_result\n    raise self._exception\nvenv/lib/python3.12/site-packages/anyio/from_thread.py:217: in _call_func\n    retval = await retval\nvenv/lib/python3.12/site-packages/starlette/testclient.py:774: in wait_startup\n    message = await receive()\nvenv/lib/python3.12/site-packages/starlette/testclient.py:771: in receive\n    self.task.result()\n/usr/lib/python3.12/concurrent/futures/_base.py:449: in result\n    return self.__get_result()\n/usr/lib/python3.12/concurrent/futures/_base.py:401: in __get_result\n    raise self._exception\nvenv/lib/python3.12/site-packages/anyio/from_thread.py:217: in _call_func\n    retval = await retval\nvenv/lib/python3.12/site-packages/starlette/testclient.py:761: in lifespan\n    await self.app(scope, self.stream_receive.receive, self.stream_send.send)\nvenv/lib/python3.12/site-packages/starlette/testclient.py:56: in __call__\n    await instance(receive, send)\nE   TypeError: object Mock can't be used in 'await' expression\n_____ ERROR at setup of TestIncidentAPI.test_incident_access_requires_auth _____\ntests/conftest.py:91: in client\n    with TestClient(app) as test_client:\nvenv/lib/python3.12/site-packages/starlette/testclient.py:745: in __enter__\n    portal.call(self.wait_startup)\nvenv/lib/python3.12/site-packages/anyio/from_thread.py:277: in call\n    return cast(T_Retval, self.start_task_soon(func, *args).result())\n/usr/lib/python3.12/concurrent/futures/_base.py:449: in result\n    return self.__get_result()\n/usr/lib/python3.12/concurrent/futures/_base.py:401: in __get_result\n    raise self._exception\nvenv/lib/python3.12/site-packages/anyio/from_thread.py:217: in _call_func\n    retval = await retval\nvenv/lib/python3.12/site-packages/starlette/testclient.py:774: in wait_startup\n    message = await receive()\nvenv/lib/python3.12/site-packages/starlette/testclient.py:771: in receive\n    self.task.result()\n/usr/lib/python3.12/concurrent/futures/_base.py:449: in result\n    return self.__get_result()\n/usr/lib/python3.12/concurrent/futures/_base.py:401: in __get_result\n    raise self._exception\nvenv/lib/python3.12/site-packages/anyio/from_thread.py:217: in _call_func\n    retval = await retval\nvenv/lib/python3.12/site-packages/starlette/testclient.py:761: in lifespan\n    await self.app(scope, self.stream_receive.receive, self.stream_send.send)\nvenv/lib/python3.12/site-packages/starlette/testclient.py:56: in __call__\n    await instance(receive, send)\nE   TypeError: object Mock can't be used in 'await' expression\n________ ERROR at setup of TestIncidentAPI.test_incident_crud_with_auth ________\ntests/conftest.py:91: in client\n    with TestClient(app) as test_client:\nvenv/lib/python3.12/site-packages/starlette/testclient.py:745: in __enter__\n    portal.call(self.wait_startup)\nvenv/lib/python3.12/site-packages/anyio/from_thread.py:277: in call\n    return cast(T_Retval, self.start_task_soon(func, *args).result())\n/usr/lib/python3.12/concurrent/futures/_base.py:449: in result\n    return self.__get_result()\n/usr/lib/python3.12/concurrent/futures/_base.py:401: in __get_result\n    raise self._exception\nvenv/lib/python3.12/site-packages/anyio/from_thread.py:217: in _call_func\n    retval = await retval\nvenv/lib/python3.12/site-packages/starlette/testclient.py:774: in wait_startup\n    message = await receive()\nvenv/lib/python3.12/site-packages/starlette/testclient.py:771: in receive\n    self.task.result()\n/usr/lib/python3.12/concurrent/futures/_base.py:449: in result\n    return self.__get_result()\n/usr/lib/python3.12/concurrent/futures/_base.py:401: in __get_result\n    raise self._exception\nvenv/lib/python3.12/site-packages/anyio/from_thread.py:217: in _call_func\n    retval = await retval\nvenv/lib/python3.12/site-packages/starlette/testclient.py:761: in lifespan\n    await self.app(scope, self.stream_receive.receive, self.stream_send.send)\nvenv/lib/python3.12/site-packages/starlette/testclient.py:56: in __call__\n    await instance(receive, send)\nE   TypeError: object Mock can't be used in 'await' expression\n=================================== FAILURES ===================================\n________________ TestIncidentAPIAsync.test_async_get_incidents _________________\ntests/api/test_incidents.py:168: in test_async_get_incidents\n    response = await async_client.get(\"/api/v1/incidents/\")\nvenv/lib/python3.12/site-packages/httpx/_client.py:1757: in get\n    return await self.request(\nvenv/lib/python3.12/site-packages/httpx/_client.py:1530: in request\n    return await self.send(request, auth=auth, follow_redirects=follow_redirects)\nvenv/lib/python3.12/site-packages/httpx/_client.py:1617: in send\n    response = await self._send_handling_auth(\nvenv/lib/python3.12/site-packages/httpx/_client.py:1645: in _send_handling_auth\n    response = await self._send_handling_redirects(\nvenv/lib/python3.12/site-packages/httpx/_client.py:1682: in _send_handling_redirects\n    response = await self._send_single_request(request)\nvenv/lib/python3.12/site-packages/httpx/_client.py:1719: in _send_single_request\n    response = await transport.handle_async_request(request)\nvenv/lib/python3.12/site-packages/httpx/_transports/asgi.py:162: in handle_async_request\n    await self.app(scope, receive, send)\nE   TypeError: object Mock can't be used in 'await' expression\n_______________ TestIncidentAPIAsync.test_async_create_incident ________________\ntests/api/test_incidents.py:177: in test_async_create_incident\n    response = await async_client.post(\"/api/v1/incidents/\", json=incident_data)\nvenv/lib/python3.12/site-packages/httpx/_client.py:1848: in post\n    return await self.request(\nvenv/lib/python3.12/site-packages/httpx/_client.py:1530: in request\n    return await self.send(request, auth=auth, follow_redirects=follow_redirects)\nvenv/lib/python3.12/site-packages/httpx/_client.py:1617: in send\n    response = await self._send_handling_auth(\nvenv/lib/python3.12/site-packages/httpx/_client.py:1645: in _send_handling_auth\n    response = await self._send_handling_redirects(\nvenv/lib/python3.12/site-packages/httpx/_client.py:1682: in _send_handling_redirects\n    response = await self._send_single_request(request)\nvenv/lib/python3.12/site-packages/httpx/_client.py:1719: in _send_single_request\n    response = await transport.handle_async_request(request)\nvenv/lib/python3.12/site-packages/httpx/_transports/asgi.py:162: in handle_async_request\n    await self.app(scope, receive, send)\nE   TypeError: object Mock can't be used in 'await' expression\n=============================== warnings summary ===============================\ntests/api/test_auth.py:12\n  /media/kensan/LinuxHDD/ITSM-ITmanagementSystem/backend/tests/api/test_auth.py:12: PytestUnknownMarkWarning: Unknown pytest.mark.api - is this a typo?  You can register custom marks to avoid this warning - for details, see https://docs.pytest.org/en/stable/how-to/mark.html\n    @pytest.mark.api\n\ntests/api/test_auth.py:13\n  /media/kensan/LinuxHDD/ITSM-ITmanagementSystem/backend/tests/api/test_auth.py:13: PytestUnknownMarkWarning: Unknown pytest.mark.auth - is this a typo?  You can register custom marks to avoid this warning - for details, see https://docs.pytest.org/en/stable/how-to/mark.html\n    @pytest.mark.auth\n\ntests/api/test_auth.py:27\n  /media/kensan/LinuxHDD/ITSM-ITmanagementSystem/backend/tests/api/test_auth.py:27: PytestUnknownMarkWarning: Unknown pytest.mark.api - is this a typo?  You can register custom marks to avoid this warning - for details, see https://docs.pytest.org/en/stable/how-to/mark.html\n    @pytest.mark.api\n\ntests/api/test_auth.py:28\n  /media/kensan/LinuxHDD/ITSM-ITmanagementSystem/backend/tests/api/test_auth.py:28: PytestUnknownMarkWarning: Unknown pytest.mark.auth - is this a typo?  You can register custom marks to avoid this warning - for details, see https://docs.pytest.org/en/stable/how-to/mark.html\n    @pytest.mark.auth\n\ntests/api/test_auth.py:40\n  /media/kensan/LinuxHDD/ITSM-ITmanagementSystem/backend/tests/api/test_auth.py:40: PytestUnknownMarkWarning: Unknown pytest.mark.api - is this a typo?  You can register custom marks to avoid this warning - for details, see https://docs.pytest.org/en/stable/how-to/mark.html\n    @pytest.mark.api\n\ntests/api/test_auth.py:41\n  /media/kensan/LinuxHDD/ITSM-ITmanagementSystem/backend/tests/api/test_auth.py:41: PytestUnknownMarkWarning: Unknown pytest.mark.auth - is this a typo?  You can register custom marks to avoid this warning - for details, see https://docs.pytest.org/en/stable/how-to/mark.html\n    @pytest.mark.auth\n\ntests/api/test_auth.py:47\n  /media/kensan/LinuxHDD/ITSM-ITmanagementSystem/backend/tests/api/test_auth.py:47: PytestUnknownMarkWarning: Unknown pytest.mark.api - is this a typo?  You can register custom marks to avoid this warning - for details, see https://docs.pytest.org/en/stable/how-to/mark.html\n    @pytest.mark.api\n\ntests/api/test_auth.py:48\n  /media/kensan/LinuxHDD/ITSM-ITmanagementSystem/backend/tests/api/test_auth.py:48: PytestUnknownMarkWarning: Unknown pytest.mark.auth - is this a typo?  You can register custom marks to avoid this warning - for details, see https://docs.pytest.org/en/stable/how-to/mark.html\n    @pytest.mark.auth\n\ntests/api/test_auth.py:65\n  /media/kensan/LinuxHDD/ITSM-ITmanagementSystem/backend/tests/api/test_auth.py:65: PytestUnknownMarkWarning: Unknown pytest.mark.api - is this a typo?  You can register custom marks to avoid this warning - for details, see https://docs.pytest.org/en/stable/how-to/mark.html\n    @pytest.mark.api\n\ntests/api/test_auth.py:66\n  /media/kensan/LinuxHDD/ITSM-ITmanagementSystem/backend/tests/api/test_auth.py:66: PytestUnknownMarkWarning: Unknown pytest.mark.auth - is this a typo?  You can register custom marks to avoid this warning - for details, see https://docs.pytest.org/en/stable/how-to/mark.html\n    @pytest.mark.auth\n\ntests/api/test_auth.py:74\n  /media/kensan/LinuxHDD/ITSM-ITmanagementSystem/backend/tests/api/test_auth.py:74: PytestUnknownMarkWarning: Unknown pytest.mark.api - is this a typo?  You can register custom marks to avoid this warning - for details, see https://docs.pytest.org/en/stable/how-to/mark.html\n    @pytest.mark.api\n\ntests/api/test_auth.py:75\n  /media/kensan/LinuxHDD/ITSM-ITmanagementSystem/backend/tests/api/test_auth.py:75: PytestUnknownMarkWarning: Unknown pytest.mark.auth - is this a typo?  You can register custom marks to avoid this warning - for details, see https://docs.pytest.org/en/stable/how-to/mark.html\n    @pytest.mark.auth\n\ntests/api/test_auth.py:87\n  /media/kensan/LinuxHDD/ITSM-ITmanagementSystem/backend/tests/api/test_auth.py:87: PytestUnknownMarkWarning: Unknown pytest.mark.api - is this a typo?  You can register custom marks to avoid this warning - for details, see https://docs.pytest.org/en/stable/how-to/mark.html\n    @pytest.mark.api\n\ntests/api/test_auth.py:88\n  /media/kensan/LinuxHDD/ITSM-ITmanagementSystem/backend/tests/api/test_auth.py:88: PytestUnknownMarkWarning: Unknown pytest.mark.auth - is this a typo?  You can register custom marks to avoid this warning - for details, see https://docs.pytest.org/en/stable/how-to/mark.html\n    @pytest.mark.auth\n\ntests/api/test_auth.py:100\n  /media/kensan/LinuxHDD/ITSM-ITmanagementSystem/backend/tests/api/test_auth.py:100: PytestUnknownMarkWarning: Unknown pytest.mark.api - is this a typo?  You can register custom marks to avoid this warning - for details, see https://docs.pytest.org/en/stable/how-to/mark.html\n    @pytest.mark.api\n\ntests/api/test_auth.py:101\n  /media/kensan/LinuxHDD/ITSM-ITmanagementSystem/backend/tests/api/test_auth.py:101: PytestUnknownMarkWarning: Unknown pytest.mark.auth - is this a typo?  You can register custom marks to avoid this warning - for details, see https://docs.pytest.org/en/stable/how-to/mark.html\n    @pytest.mark.auth\n\ntests/api/test_auth.py:107\n  /media/kensan/LinuxHDD/ITSM-ITmanagementSystem/backend/tests/api/test_auth.py:107: PytestUnknownMarkWarning: Unknown pytest.mark.api - is this a typo?  You can register custom marks to avoid this warning - for details, see https://docs.pytest.org/en/stable/how-to/mark.html\n    @pytest.mark.api\n\ntests/api/test_auth.py:108\n  /media/kensan/LinuxHDD/ITSM-ITmanagementSystem/backend/tests/api/test_auth.py:108: PytestUnknownMarkWarning: Unknown pytest.mark.auth - is this a typo?  You can register custom marks to avoid this warning - for details, see https://docs.pytest.org/en/stable/how-to/mark.html\n    @pytest.mark.auth\n\ntests/api/test_auth.py:118\n  /media/kensan/LinuxHDD/ITSM-ITmanagementSystem/backend/tests/api/test_auth.py:118: PytestUnknownMarkWarning: Unknown pytest.mark.api - is this a typo?  You can register custom marks to avoid this warning - for details, see https://docs.pytest.org/en/stable/how-to/mark.html\n    @pytest.mark.api\n\ntests/api/test_auth.py:119\n  /media/kensan/LinuxHDD/ITSM-ITmanagementSystem/backend/tests/api/test_auth.py:119: PytestUnknownMarkWarning: Unknown pytest.mark.auth - is this a typo?  You can register custom marks to avoid this warning - for details, see https://docs.pytest.org/en/stable/how-to/mark.html\n    @pytest.mark.auth\n\ntests/api/test_auth.py:126\n  /media/kensan/LinuxHDD/ITSM-ITmanagementSystem/backend/tests/api/test_auth.py:126: PytestUnknownMarkWarning: Unknown pytest.mark.api - is this a typo?  You can register custom marks to avoid this warning - for details, see https://docs.pytest.org/en/stable/how-to/mark.html\n    @pytest.mark.api\n\ntests/api/test_auth.py:127\n  /media/kensan/LinuxHDD/ITSM-ITmanagementSystem/backend/tests/api/test_auth.py:127: PytestUnknownMarkWarning: Unknown pytest.mark.auth - is this a typo?  You can register custom marks to avoid this warning - for details, see https://docs.pytest.org/en/stable/how-to/mark.html\n    @pytest.mark.auth\n\ntests/api/test_auth.py:138\n  /media/kensan/LinuxHDD/ITSM-ITmanagementSystem/backend/tests/api/test_auth.py:138: PytestUnknownMarkWarning: Unknown pytest.mark.api - is this a typo?  You can register custom marks to avoid this warning - for details, see https://docs.pytest.org/en/stable/how-to/mark.html\n    @pytest.mark.api\n\ntests/api/test_auth.py:139\n  /media/kensan/LinuxHDD/ITSM-ITmanagementSystem/backend/tests/api/test_auth.py:139: PytestUnknownMarkWarning: Unknown pytest.mark.auth - is this a typo?  You can register custom marks to avoid this warning - for details, see https://docs.pytest.org/en/stable/how-to/mark.html\n    @pytest.mark.auth\n\ntests/api/test_auth.py:150\n  /media/kensan/LinuxHDD/ITSM-ITmanagementSystem/backend/tests/api/test_auth.py:150: PytestUnknownMarkWarning: Unknown pytest.mark.api - is this a typo?  You can register custom marks to avoid this warning - for details, see https://docs.pytest.org/en/stable/how-to/mark.html\n    @pytest.mark.api\n\ntests/api/test_auth.py:151\n  /media/kensan/LinuxHDD/ITSM-ITmanagementSystem/backend/tests/api/test_auth.py:151: PytestUnknownMarkWarning: Unknown pytest.mark.auth - is this a typo?  You can register custom marks to avoid this warning - for details, see https://docs.pytest.org/en/stable/how-to/mark.html\n    @pytest.mark.auth\n\ntests/api/test_auth.py:158\n  /media/kensan/LinuxHDD/ITSM-ITmanagementSystem/backend/tests/api/test_auth.py:158: PytestUnknownMarkWarning: Unknown pytest.mark.api - is this a typo?  You can register custom marks to avoid this warning - for details, see https://docs.pytest.org/en/stable/how-to/mark.html\n    @pytest.mark.api\n\ntests/api/test_auth.py:159\n  /media/kensan/LinuxHDD/ITSM-ITmanagementSystem/backend/tests/api/test_auth.py:159: PytestUnknownMarkWarning: Unknown pytest.mark.auth - is this a typo?  You can register custom marks to avoid this warning - for details, see https://docs.pytest.org/en/stable/how-to/mark.html\n    @pytest.mark.auth\n\ntests/api/test_auth.py:171\n  /media/kensan/LinuxHDD/ITSM-ITmanagementSystem/backend/tests/api/test_auth.py:171: PytestUnknownMarkWarning: Unknown pytest.mark.api - is this a typo?  You can register custom marks to avoid this warning - for details, see https://docs.pytest.org/en/stable/how-to/mark.html\n    @pytest.mark.api\n\ntests/api/test_auth.py:172\n  /media/kensan/LinuxHDD/ITSM-ITmanagementSystem/backend/tests/api/test_auth.py:172: PytestUnknownMarkWarning: Unknown pytest.mark.auth - is this a typo?  You can register custom marks to avoid this warning - for details, see https://docs.pytest.org/en/stable/how-to/mark.html\n    @pytest.mark.auth\n\ntests/api/test_auth.py:182\n  /media/kensan/LinuxHDD/ITSM-ITmanagementSystem/backend/tests/api/test_auth.py:182: PytestUnknownMarkWarning: Unknown pytest.mark.api - is this a typo?  You can register custom marks to avoid this warning - for details, see https://docs.pytest.org/en/stable/how-to/mark.html\n    @pytest.mark.api\n\ntests/api/test_auth.py:183\n  /media/kensan/LinuxHDD/ITSM-ITmanagementSystem/backend/tests/api/test_auth.py:183: PytestUnknownMarkWarning: Unknown pytest.mark.auth - is this a typo?  You can register custom marks to avoid this warning - for details, see https://docs.pytest.org/en/stable/how-to/mark.html\n    @pytest.mark.auth\n\ntests/api/test_incidents.py:13\n  /media/kensan/LinuxHDD/ITSM-ITmanagementSystem/backend/tests/api/test_incidents.py:13: PytestUnknownMarkWarning: Unknown pytest.mark.api - is this a typo?  You can register custom marks to avoid this warning - for details, see https://docs.pytest.org/en/stable/how-to/mark.html\n    @pytest.mark.api\n\ntests/api/test_incidents.py:21\n  /media/kensan/LinuxHDD/ITSM-ITmanagementSystem/backend/tests/api/test_incidents.py:21: PytestUnknownMarkWarning: Unknown pytest.mark.api - is this a typo?  You can register custom marks to avoid this warning - for details, see https://docs.pytest.org/en/stable/how-to/mark.html\n    @pytest.mark.api\n\ntests/api/test_incidents.py:33\n  /media/kensan/LinuxHDD/ITSM-ITmanagementSystem/backend/tests/api/test_incidents.py:33: PytestUnknownMarkWarning: Unknown pytest.mark.api - is this a typo?  You can register custom marks to avoid this warning - for details, see https://docs.pytest.org/en/stable/how-to/mark.html\n    @pytest.mark.api\n\ntests/api/test_incidents.py:47\n  /media/kensan/LinuxHDD/ITSM-ITmanagementSystem/backend/tests/api/test_incidents.py:47: PytestUnknownMarkWarning: Unknown pytest.mark.api - is this a typo?  You can register custom marks to avoid this warning - for details, see https://docs.pytest.org/en/stable/how-to/mark.html\n    @pytest.mark.api\n\ntests/api/test_incidents.py:62\n  /media/kensan/LinuxHDD/ITSM-ITmanagementSystem/backend/tests/api/test_incidents.py:62: PytestUnknownMarkWarning: Unknown pytest.mark.api - is this a typo?  You can register custom marks to avoid this warning - for details, see https://docs.pytest.org/en/stable/how-to/mark.html\n    @pytest.mark.api\n\ntests/api/test_incidents.py:77\n  /media/kensan/LinuxHDD/ITSM-ITmanagementSystem/backend/tests/api/test_incidents.py:77: PytestUnknownMarkWarning: Unknown pytest.mark.api - is this a typo?  You can register custom marks to avoid this warning - for details, see https://docs.pytest.org/en/stable/how-to/mark.html\n    @pytest.mark.api\n\ntests/api/test_incidents.py:86\n  /media/kensan/LinuxHDD/ITSM-ITmanagementSystem/backend/tests/api/test_incidents.py:86: PytestUnknownMarkWarning: Unknown pytest.mark.api - is this a typo?  You can register custom marks to avoid this warning - for details, see https://docs.pytest.org/en/stable/how-to/mark.html\n    @pytest.mark.api\n\ntests/api/test_incidents.py:95\n  /media/kensan/LinuxHDD/ITSM-ITmanagementSystem/backend/tests/api/test_incidents.py:95: PytestUnknownMarkWarning: Unknown pytest.mark.api - is this a typo?  You can register custom marks to avoid this warning - for details, see https://docs.pytest.org/en/stable/how-to/mark.html\n    @pytest.mark.api\n\ntests/api/test_incidents.py:105\n  /media/kensan/LinuxHDD/ITSM-ITmanagementSystem/backend/tests/api/test_incidents.py:105: PytestUnknownMarkWarning: Unknown pytest.mark.api - is this a typo?  You can register custom marks to avoid this warning - for details, see https://docs.pytest.org/en/stable/how-to/mark.html\n    @pytest.mark.api\n\ntests/api/test_incidents.py:119\n  /media/kensan/LinuxHDD/ITSM-ITmanagementSystem/backend/tests/api/test_incidents.py:119: PytestUnknownMarkWarning: Unknown pytest.mark.api - is this a typo?  You can register custom marks to avoid this warning - for details, see https://docs.pytest.org/en/stable/how-to/mark.html\n    @pytest.mark.api\n\ntests/api/test_incidents.py:135\n  /media/kensan/LinuxHDD/ITSM-ITmanagementSystem/backend/tests/api/test_incidents.py:135: PytestUnknownMarkWarning: Unknown pytest.mark.api - is this a typo?  You can register custom marks to avoid this warning - for details, see https://docs.pytest.org/en/stable/how-to/mark.html\n    @pytest.mark.api\n\ntests/api/test_incidents.py:136\n  /media/kensan/LinuxHDD/ITSM-ITmanagementSystem/backend/tests/api/test_incidents.py:136: PytestUnknownMarkWarning: Unknown pytest.mark.auth - is this a typo?  You can register custom marks to avoid this warning - for details, see https://docs.pytest.org/en/stable/how-to/mark.html\n    @pytest.mark.auth\n\ntests/api/test_incidents.py:145\n  /media/kensan/LinuxHDD/ITSM-ITmanagementSystem/backend/tests/api/test_incidents.py:145: PytestUnknownMarkWarning: Unknown pytest.mark.api - is this a typo?  You can register custom marks to avoid this warning - for details, see https://docs.pytest.org/en/stable/how-to/mark.html\n    @pytest.mark.api\n\ntests/api/test_incidents.py:146\n  /media/kensan/LinuxHDD/ITSM-ITmanagementSystem/backend/tests/api/test_incidents.py:146: PytestUnknownMarkWarning: Unknown pytest.mark.auth - is this a typo?  You can register custom marks to avoid this warning - for details, see https://docs.pytest.org/en/stable/how-to/mark.html\n    @pytest.mark.auth\n\ntests/api/test_incidents.py:165\n  /media/kensan/LinuxHDD/ITSM-ITmanagementSystem/backend/tests/api/test_incidents.py:165: PytestUnknownMarkWarning: Unknown pytest.mark.api - is this a typo?  You can register custom marks to avoid this warning - for details, see https://docs.pytest.org/en/stable/how-to/mark.html\n    @pytest.mark.api\n\ntests/api/test_incidents.py:174\n  /media/kensan/LinuxHDD/ITSM-ITmanagementSystem/backend/tests/api/test_incidents.py:174: PytestUnknownMarkWarning: Unknown pytest.mark.api - is this a typo?  You can register custom marks to avoid this warning - for details, see https://docs.pytest.org/en/stable/how-to/mark.html\n    @pytest.mark.api\n\n-- Docs: https://docs.pytest.org/en/stable/how-to/capture-warnings.html\n=========================== short test summary info ============================\nFAILED tests/api/test_incidents.py::TestIncidentAPIAsync::test_async_get_incidents\nFAILED tests/api/test_incidents.py::TestIncidentAPIAsync::test_async_create_incident\nERROR tests/api/test_auth.py::TestAuthAPI::test_login_success - TypeError: ob...\nERROR tests/api/test_auth.py::TestAuthAPI::test_login_invalid_credentials - T...\nERROR tests/api/test_auth.py::TestAuthAPI::test_login_missing_credentials - T...\nERROR tests/api/test_auth.py::TestAuthAPI::test_register_success - TypeError:...\nERROR tests/api/test_auth.py::TestAuthAPI::test_register_duplicate_email - Ty...\nERROR tests/api/test_auth.py::TestAuthAPI::test_register_invalid_email - Type...\nERROR tests/api/test_auth.py::TestAuthAPI::test_get_current_user - TypeError:...\nERROR tests/api/test_auth.py::TestAuthAPI::test_get_current_user_unauthorized\nERROR tests/api/test_auth.py::TestAuthAPI::test_token_refresh - TypeError: ob...\nERROR tests/api/test_auth.py::TestAuthAPI::test_logout - TypeError: object Mo...\nERROR tests/api/test_auth.py::TestAuthAPI::test_change_password - TypeError: ...\nERROR tests/api/test_auth.py::TestAuthAPI::test_change_password_invalid_current\nERROR tests/api/test_auth.py::TestAuthAPI::test_forgot_password - TypeError: ...\nERROR tests/api/test_auth.py::TestAuthAPI::test_reset_password - TypeError: o...\nERROR tests/api/test_auth.py::TestAuthAPI::test_verify_token - TypeError: obj...\nERROR tests/api/test_auth.py::TestAuthAPI::test_verify_invalid_token - TypeEr...\nERROR tests/api/test_incidents.py::TestIncidentAPI::test_get_incidents_list\nERROR tests/api/test_incidents.py::TestIncidentAPI::test_create_incident - Ty...\nERROR tests/api/test_incidents.py::TestIncidentAPI::test_get_incident_by_id\nERROR tests/api/test_incidents.py::TestIncidentAPI::test_update_incident - Ty...\nERROR tests/api/test_incidents.py::TestIncidentAPI::test_delete_incident - Ty...\nERROR tests/api/test_incidents.py::TestIncidentAPI::test_filter_incidents_by_status\nERROR tests/api/test_incidents.py::TestIncidentAPI::test_filter_incidents_by_priority\nERROR tests/api/test_incidents.py::TestIncidentAPI::test_search_incidents - T...\nERROR tests/api/test_incidents.py::TestIncidentAPI::test_assign_incident - Ty...\nERROR tests/api/test_incidents.py::TestIncidentAPI::test_incident_validation_errors\nERROR tests/api/test_incidents.py::TestIncidentAPI::test_incident_access_requires_auth\nERROR tests/api/test_incidents.py::TestIncidentAPI::test_incident_crud_with_auth\n================== 2 failed, 48 warnings, 28 errors in 2.82s ===================\n",
    "errors": "",
    "executed_at": "2025-08-01T16:18:38.027189"
  },
  "errors": [],
  "fixes": []
}